{
 "cells": [
  {
   "cell_type": "code",
   "execution_count": 10,
   "metadata": {},
   "outputs": [],
   "source": [
    "from telegram.ext import Updater\n",
    "updater = Updater(token='1598945607:AAGbVZM9ZwoHsDSy___o4B_kGfbUtKSl5AY', use_context=True)\n",
    "dispatcher = updater.dispatcher\n",
    "import logging\n",
    "logging.basicConfig(format='%(asctime)s - %(name)s - %(levelname)s - %(message)s',\n",
    "                     level=logging.INFO)\n",
    "def start(update, context):\n",
    "    context.bot.send_message(chat_id=update.effective_chat.id, text=\"Daily inspiration about topological quantum computing\")"
   ]
  },
  {
   "cell_type": "code",
   "execution_count": 11,
   "metadata": {},
   "outputs": [
    {
     "name": "stderr",
     "output_type": "stream",
     "text": [
      "2021-01-25 15:25:06,300 - apscheduler.scheduler - INFO - Scheduler started\n"
     ]
    },
    {
     "data": {
      "text/plain": [
       "<queue.Queue at 0x1c67342f9a0>"
      ]
     },
     "execution_count": 11,
     "metadata": {},
     "output_type": "execute_result"
    },
    {
     "name": "stderr",
     "output_type": "stream",
     "text": [
      "2021-01-25 15:25:06,464 - telegram.ext.updater - ERROR - Error while getting Updates: Conflict: terminated by other getUpdates request; make sure that only one bot instance is running\n",
      "2021-01-25 15:25:06,467 - telegram.ext.dispatcher - ERROR - No error handlers are registered, logging exception.\n",
      "Traceback (most recent call last):\n",
      "  File \"C:\\Users\\tesya\\anaconda3\\lib\\site-packages\\telegram\\ext\\updater.py\", line 465, in _network_loop_retry\n",
      "    if not action_cb():\n",
      "  File \"C:\\Users\\tesya\\anaconda3\\lib\\site-packages\\telegram\\ext\\updater.py\", line 416, in polling_action_cb\n",
      "    updates = self.bot.get_updates(\n",
      "  File \"<decorator-gen-148>\", line 2, in get_updates\n",
      "  File \"C:\\Users\\tesya\\anaconda3\\lib\\site-packages\\telegram\\bot.py\", line 135, in decorator\n",
      "    result = func(*args, **kwargs)\n",
      "  File \"C:\\Users\\tesya\\anaconda3\\lib\\site-packages\\telegram\\bot.py\", line 2638, in get_updates\n",
      "    result = self._post(\n",
      "  File \"C:\\Users\\tesya\\anaconda3\\lib\\site-packages\\telegram\\bot.py\", line 245, in _post\n",
      "    return self.request.post(f'{self.base_url}/{endpoint}', data=data, timeout=timeout)\n",
      "  File \"C:\\Users\\tesya\\anaconda3\\lib\\site-packages\\telegram\\utils\\request.py\", line 349, in post\n",
      "    result = self._request_wrapper(\n",
      "  File \"C:\\Users\\tesya\\anaconda3\\lib\\site-packages\\telegram\\utils\\request.py\", line 276, in _request_wrapper\n",
      "    raise Conflict(message)\n",
      "telegram.error.Conflict: Conflict: terminated by other getUpdates request; make sure that only one bot instance is running\n",
      "2021-01-25 15:25:10,487 - telegram.ext.updater - ERROR - Error while getting Updates: Conflict: terminated by other getUpdates request; make sure that only one bot instance is running\n",
      "2021-01-25 15:25:10,489 - telegram.ext.dispatcher - ERROR - No error handlers are registered, logging exception.\n",
      "Traceback (most recent call last):\n",
      "  File \"C:\\Users\\tesya\\anaconda3\\lib\\site-packages\\telegram\\ext\\updater.py\", line 465, in _network_loop_retry\n",
      "    if not action_cb():\n",
      "  File \"C:\\Users\\tesya\\anaconda3\\lib\\site-packages\\telegram\\ext\\updater.py\", line 416, in polling_action_cb\n",
      "    updates = self.bot.get_updates(\n",
      "  File \"<decorator-gen-148>\", line 2, in get_updates\n",
      "  File \"C:\\Users\\tesya\\anaconda3\\lib\\site-packages\\telegram\\bot.py\", line 135, in decorator\n",
      "    result = func(*args, **kwargs)\n",
      "  File \"C:\\Users\\tesya\\anaconda3\\lib\\site-packages\\telegram\\bot.py\", line 2638, in get_updates\n",
      "    result = self._post(\n",
      "  File \"C:\\Users\\tesya\\anaconda3\\lib\\site-packages\\telegram\\bot.py\", line 245, in _post\n",
      "    return self.request.post(f'{self.base_url}/{endpoint}', data=data, timeout=timeout)\n",
      "  File \"C:\\Users\\tesya\\anaconda3\\lib\\site-packages\\telegram\\utils\\request.py\", line 349, in post\n",
      "    result = self._request_wrapper(\n",
      "  File \"C:\\Users\\tesya\\anaconda3\\lib\\site-packages\\telegram\\utils\\request.py\", line 276, in _request_wrapper\n",
      "    raise Conflict(message)\n",
      "telegram.error.Conflict: Conflict: terminated by other getUpdates request; make sure that only one bot instance is running\n",
      "2021-01-25 15:25:11,511 - telegram.ext.updater - ERROR - Error while getting Updates: Conflict: terminated by other getUpdates request; make sure that only one bot instance is running\n",
      "2021-01-25 15:25:11,512 - telegram.ext.dispatcher - ERROR - No error handlers are registered, logging exception.\n",
      "Traceback (most recent call last):\n",
      "  File \"C:\\Users\\tesya\\anaconda3\\lib\\site-packages\\telegram\\ext\\updater.py\", line 465, in _network_loop_retry\n",
      "    if not action_cb():\n",
      "  File \"C:\\Users\\tesya\\anaconda3\\lib\\site-packages\\telegram\\ext\\updater.py\", line 416, in polling_action_cb\n",
      "    updates = self.bot.get_updates(\n",
      "  File \"<decorator-gen-148>\", line 2, in get_updates\n",
      "  File \"C:\\Users\\tesya\\anaconda3\\lib\\site-packages\\telegram\\bot.py\", line 135, in decorator\n",
      "    result = func(*args, **kwargs)\n",
      "  File \"C:\\Users\\tesya\\anaconda3\\lib\\site-packages\\telegram\\bot.py\", line 2638, in get_updates\n",
      "    result = self._post(\n",
      "  File \"C:\\Users\\tesya\\anaconda3\\lib\\site-packages\\telegram\\bot.py\", line 245, in _post\n",
      "    return self.request.post(f'{self.base_url}/{endpoint}', data=data, timeout=timeout)\n",
      "  File \"C:\\Users\\tesya\\anaconda3\\lib\\site-packages\\telegram\\utils\\request.py\", line 349, in post\n",
      "    result = self._request_wrapper(\n",
      "  File \"C:\\Users\\tesya\\anaconda3\\lib\\site-packages\\telegram\\utils\\request.py\", line 276, in _request_wrapper\n",
      "    raise Conflict(message)\n",
      "telegram.error.Conflict: Conflict: terminated by other getUpdates request; make sure that only one bot instance is running\n",
      "2021-01-25 15:25:16,038 - telegram.ext.updater - ERROR - Error while getting Updates: Conflict: terminated by other getUpdates request; make sure that only one bot instance is running\n",
      "2021-01-25 15:25:16,039 - telegram.ext.dispatcher - ERROR - No error handlers are registered, logging exception.\n",
      "Traceback (most recent call last):\n",
      "  File \"C:\\Users\\tesya\\anaconda3\\lib\\site-packages\\telegram\\ext\\updater.py\", line 465, in _network_loop_retry\n",
      "    if not action_cb():\n",
      "  File \"C:\\Users\\tesya\\anaconda3\\lib\\site-packages\\telegram\\ext\\updater.py\", line 416, in polling_action_cb\n",
      "    updates = self.bot.get_updates(\n",
      "  File \"<decorator-gen-148>\", line 2, in get_updates\n",
      "  File \"C:\\Users\\tesya\\anaconda3\\lib\\site-packages\\telegram\\bot.py\", line 135, in decorator\n",
      "    result = func(*args, **kwargs)\n",
      "  File \"C:\\Users\\tesya\\anaconda3\\lib\\site-packages\\telegram\\bot.py\", line 2638, in get_updates\n",
      "    result = self._post(\n",
      "  File \"C:\\Users\\tesya\\anaconda3\\lib\\site-packages\\telegram\\bot.py\", line 245, in _post\n",
      "    return self.request.post(f'{self.base_url}/{endpoint}', data=data, timeout=timeout)\n",
      "  File \"C:\\Users\\tesya\\anaconda3\\lib\\site-packages\\telegram\\utils\\request.py\", line 349, in post\n",
      "    result = self._request_wrapper(\n",
      "  File \"C:\\Users\\tesya\\anaconda3\\lib\\site-packages\\telegram\\utils\\request.py\", line 276, in _request_wrapper\n",
      "    raise Conflict(message)\n",
      "telegram.error.Conflict: Conflict: terminated by other getUpdates request; make sure that only one bot instance is running\n",
      "2021-01-25 15:25:17,555 - telegram.ext.updater - ERROR - Error while getting Updates: Conflict: terminated by other getUpdates request; make sure that only one bot instance is running\n",
      "2021-01-25 15:25:17,556 - telegram.ext.dispatcher - ERROR - No error handlers are registered, logging exception.\n",
      "Traceback (most recent call last):\n",
      "  File \"C:\\Users\\tesya\\anaconda3\\lib\\site-packages\\telegram\\ext\\updater.py\", line 465, in _network_loop_retry\n",
      "    if not action_cb():\n",
      "  File \"C:\\Users\\tesya\\anaconda3\\lib\\site-packages\\telegram\\ext\\updater.py\", line 416, in polling_action_cb\n",
      "    updates = self.bot.get_updates(\n",
      "  File \"<decorator-gen-148>\", line 2, in get_updates\n",
      "  File \"C:\\Users\\tesya\\anaconda3\\lib\\site-packages\\telegram\\bot.py\", line 135, in decorator\n",
      "    result = func(*args, **kwargs)\n",
      "  File \"C:\\Users\\tesya\\anaconda3\\lib\\site-packages\\telegram\\bot.py\", line 2638, in get_updates\n",
      "    result = self._post(\n",
      "  File \"C:\\Users\\tesya\\anaconda3\\lib\\site-packages\\telegram\\bot.py\", line 245, in _post\n",
      "    return self.request.post(f'{self.base_url}/{endpoint}', data=data, timeout=timeout)\n",
      "  File \"C:\\Users\\tesya\\anaconda3\\lib\\site-packages\\telegram\\utils\\request.py\", line 349, in post\n",
      "    result = self._request_wrapper(\n",
      "  File \"C:\\Users\\tesya\\anaconda3\\lib\\site-packages\\telegram\\utils\\request.py\", line 276, in _request_wrapper\n",
      "    raise Conflict(message)\n",
      "telegram.error.Conflict: Conflict: terminated by other getUpdates request; make sure that only one bot instance is running\n",
      "2021-01-25 15:25:22,824 - telegram.ext.updater - ERROR - Error while getting Updates: Conflict: terminated by other getUpdates request; make sure that only one bot instance is running\n",
      "2021-01-25 15:25:22,825 - telegram.ext.dispatcher - ERROR - No error handlers are registered, logging exception.\n",
      "Traceback (most recent call last):\n",
      "  File \"C:\\Users\\tesya\\anaconda3\\lib\\site-packages\\telegram\\ext\\updater.py\", line 465, in _network_loop_retry\n",
      "    if not action_cb():\n",
      "  File \"C:\\Users\\tesya\\anaconda3\\lib\\site-packages\\telegram\\ext\\updater.py\", line 416, in polling_action_cb\n",
      "    updates = self.bot.get_updates(\n",
      "  File \"<decorator-gen-148>\", line 2, in get_updates\n",
      "  File \"C:\\Users\\tesya\\anaconda3\\lib\\site-packages\\telegram\\bot.py\", line 135, in decorator\n",
      "    result = func(*args, **kwargs)\n",
      "  File \"C:\\Users\\tesya\\anaconda3\\lib\\site-packages\\telegram\\bot.py\", line 2638, in get_updates\n",
      "    result = self._post(\n",
      "  File \"C:\\Users\\tesya\\anaconda3\\lib\\site-packages\\telegram\\bot.py\", line 245, in _post\n",
      "    return self.request.post(f'{self.base_url}/{endpoint}', data=data, timeout=timeout)\n",
      "  File \"C:\\Users\\tesya\\anaconda3\\lib\\site-packages\\telegram\\utils\\request.py\", line 349, in post\n",
      "    result = self._request_wrapper(\n",
      "  File \"C:\\Users\\tesya\\anaconda3\\lib\\site-packages\\telegram\\utils\\request.py\", line 276, in _request_wrapper\n",
      "    raise Conflict(message)\n",
      "telegram.error.Conflict: Conflict: terminated by other getUpdates request; make sure that only one bot instance is running\n"
     ]
    },
    {
     "name": "stderr",
     "output_type": "stream",
     "text": [
      "2021-01-25 15:25:25,095 - telegram.ext.updater - ERROR - Error while getting Updates: Conflict: terminated by other getUpdates request; make sure that only one bot instance is running\n",
      "2021-01-25 15:25:25,096 - telegram.ext.dispatcher - ERROR - No error handlers are registered, logging exception.\n",
      "Traceback (most recent call last):\n",
      "  File \"C:\\Users\\tesya\\anaconda3\\lib\\site-packages\\telegram\\ext\\updater.py\", line 465, in _network_loop_retry\n",
      "    if not action_cb():\n",
      "  File \"C:\\Users\\tesya\\anaconda3\\lib\\site-packages\\telegram\\ext\\updater.py\", line 416, in polling_action_cb\n",
      "    updates = self.bot.get_updates(\n",
      "  File \"<decorator-gen-148>\", line 2, in get_updates\n",
      "  File \"C:\\Users\\tesya\\anaconda3\\lib\\site-packages\\telegram\\bot.py\", line 135, in decorator\n",
      "    result = func(*args, **kwargs)\n",
      "  File \"C:\\Users\\tesya\\anaconda3\\lib\\site-packages\\telegram\\bot.py\", line 2638, in get_updates\n",
      "    result = self._post(\n",
      "  File \"C:\\Users\\tesya\\anaconda3\\lib\\site-packages\\telegram\\bot.py\", line 245, in _post\n",
      "    return self.request.post(f'{self.base_url}/{endpoint}', data=data, timeout=timeout)\n",
      "  File \"C:\\Users\\tesya\\anaconda3\\lib\\site-packages\\telegram\\utils\\request.py\", line 349, in post\n",
      "    result = self._request_wrapper(\n",
      "  File \"C:\\Users\\tesya\\anaconda3\\lib\\site-packages\\telegram\\utils\\request.py\", line 276, in _request_wrapper\n",
      "    raise Conflict(message)\n",
      "telegram.error.Conflict: Conflict: terminated by other getUpdates request; make sure that only one bot instance is running\n",
      "2021-01-25 15:25:28,488 - telegram.ext.updater - ERROR - Error while getting Updates: Conflict: terminated by other getUpdates request; make sure that only one bot instance is running\n",
      "2021-01-25 15:25:28,488 - telegram.ext.dispatcher - ERROR - No error handlers are registered, logging exception.\n",
      "Traceback (most recent call last):\n",
      "  File \"C:\\Users\\tesya\\anaconda3\\lib\\site-packages\\telegram\\ext\\updater.py\", line 465, in _network_loop_retry\n",
      "    if not action_cb():\n",
      "  File \"C:\\Users\\tesya\\anaconda3\\lib\\site-packages\\telegram\\ext\\updater.py\", line 416, in polling_action_cb\n",
      "    updates = self.bot.get_updates(\n",
      "  File \"<decorator-gen-148>\", line 2, in get_updates\n",
      "  File \"C:\\Users\\tesya\\anaconda3\\lib\\site-packages\\telegram\\bot.py\", line 135, in decorator\n",
      "    result = func(*args, **kwargs)\n",
      "  File \"C:\\Users\\tesya\\anaconda3\\lib\\site-packages\\telegram\\bot.py\", line 2638, in get_updates\n",
      "    result = self._post(\n",
      "  File \"C:\\Users\\tesya\\anaconda3\\lib\\site-packages\\telegram\\bot.py\", line 245, in _post\n",
      "    return self.request.post(f'{self.base_url}/{endpoint}', data=data, timeout=timeout)\n",
      "  File \"C:\\Users\\tesya\\anaconda3\\lib\\site-packages\\telegram\\utils\\request.py\", line 349, in post\n",
      "    result = self._request_wrapper(\n",
      "  File \"C:\\Users\\tesya\\anaconda3\\lib\\site-packages\\telegram\\utils\\request.py\", line 276, in _request_wrapper\n",
      "    raise Conflict(message)\n",
      "telegram.error.Conflict: Conflict: terminated by other getUpdates request; make sure that only one bot instance is running\n",
      "2021-01-25 15:25:32,509 - telegram.ext.updater - ERROR - Error while getting Updates: Conflict: terminated by other getUpdates request; make sure that only one bot instance is running\n",
      "2021-01-25 15:25:32,510 - telegram.ext.dispatcher - ERROR - No error handlers are registered, logging exception.\n",
      "Traceback (most recent call last):\n",
      "  File \"C:\\Users\\tesya\\anaconda3\\lib\\site-packages\\telegram\\ext\\updater.py\", line 465, in _network_loop_retry\n",
      "    if not action_cb():\n",
      "  File \"C:\\Users\\tesya\\anaconda3\\lib\\site-packages\\telegram\\ext\\updater.py\", line 416, in polling_action_cb\n",
      "    updates = self.bot.get_updates(\n",
      "  File \"<decorator-gen-148>\", line 2, in get_updates\n",
      "  File \"C:\\Users\\tesya\\anaconda3\\lib\\site-packages\\telegram\\bot.py\", line 135, in decorator\n",
      "    result = func(*args, **kwargs)\n",
      "  File \"C:\\Users\\tesya\\anaconda3\\lib\\site-packages\\telegram\\bot.py\", line 2638, in get_updates\n",
      "    result = self._post(\n",
      "  File \"C:\\Users\\tesya\\anaconda3\\lib\\site-packages\\telegram\\bot.py\", line 245, in _post\n",
      "    return self.request.post(f'{self.base_url}/{endpoint}', data=data, timeout=timeout)\n",
      "  File \"C:\\Users\\tesya\\anaconda3\\lib\\site-packages\\telegram\\utils\\request.py\", line 349, in post\n",
      "    result = self._request_wrapper(\n",
      "  File \"C:\\Users\\tesya\\anaconda3\\lib\\site-packages\\telegram\\utils\\request.py\", line 276, in _request_wrapper\n",
      "    raise Conflict(message)\n",
      "telegram.error.Conflict: Conflict: terminated by other getUpdates request; make sure that only one bot instance is running\n",
      "2021-01-25 15:25:37,590 - telegram.ext.updater - ERROR - Error while getting Updates: Conflict: terminated by other getUpdates request; make sure that only one bot instance is running\n",
      "2021-01-25 15:25:37,591 - telegram.ext.dispatcher - ERROR - No error handlers are registered, logging exception.\n",
      "Traceback (most recent call last):\n",
      "  File \"C:\\Users\\tesya\\anaconda3\\lib\\site-packages\\telegram\\ext\\updater.py\", line 465, in _network_loop_retry\n",
      "    if not action_cb():\n",
      "  File \"C:\\Users\\tesya\\anaconda3\\lib\\site-packages\\telegram\\ext\\updater.py\", line 416, in polling_action_cb\n",
      "    updates = self.bot.get_updates(\n",
      "  File \"<decorator-gen-148>\", line 2, in get_updates\n",
      "  File \"C:\\Users\\tesya\\anaconda3\\lib\\site-packages\\telegram\\bot.py\", line 135, in decorator\n",
      "    result = func(*args, **kwargs)\n",
      "  File \"C:\\Users\\tesya\\anaconda3\\lib\\site-packages\\telegram\\bot.py\", line 2638, in get_updates\n",
      "    result = self._post(\n",
      "  File \"C:\\Users\\tesya\\anaconda3\\lib\\site-packages\\telegram\\bot.py\", line 245, in _post\n",
      "    return self.request.post(f'{self.base_url}/{endpoint}', data=data, timeout=timeout)\n",
      "  File \"C:\\Users\\tesya\\anaconda3\\lib\\site-packages\\telegram\\utils\\request.py\", line 349, in post\n",
      "    result = self._request_wrapper(\n",
      "  File \"C:\\Users\\tesya\\anaconda3\\lib\\site-packages\\telegram\\utils\\request.py\", line 276, in _request_wrapper\n",
      "    raise Conflict(message)\n",
      "telegram.error.Conflict: Conflict: terminated by other getUpdates request; make sure that only one bot instance is running\n",
      "2021-01-25 15:25:42,108 - telegram.ext.updater - ERROR - Error while getting Updates: Conflict: terminated by other getUpdates request; make sure that only one bot instance is running\n",
      "2021-01-25 15:25:42,109 - telegram.ext.dispatcher - ERROR - No error handlers are registered, logging exception.\n",
      "Traceback (most recent call last):\n",
      "  File \"C:\\Users\\tesya\\anaconda3\\lib\\site-packages\\telegram\\ext\\updater.py\", line 465, in _network_loop_retry\n",
      "    if not action_cb():\n",
      "  File \"C:\\Users\\tesya\\anaconda3\\lib\\site-packages\\telegram\\ext\\updater.py\", line 416, in polling_action_cb\n",
      "    updates = self.bot.get_updates(\n",
      "  File \"<decorator-gen-148>\", line 2, in get_updates\n",
      "  File \"C:\\Users\\tesya\\anaconda3\\lib\\site-packages\\telegram\\bot.py\", line 135, in decorator\n",
      "    result = func(*args, **kwargs)\n",
      "  File \"C:\\Users\\tesya\\anaconda3\\lib\\site-packages\\telegram\\bot.py\", line 2638, in get_updates\n",
      "    result = self._post(\n",
      "  File \"C:\\Users\\tesya\\anaconda3\\lib\\site-packages\\telegram\\bot.py\", line 245, in _post\n",
      "    return self.request.post(f'{self.base_url}/{endpoint}', data=data, timeout=timeout)\n",
      "  File \"C:\\Users\\tesya\\anaconda3\\lib\\site-packages\\telegram\\utils\\request.py\", line 349, in post\n",
      "    result = self._request_wrapper(\n",
      "  File \"C:\\Users\\tesya\\anaconda3\\lib\\site-packages\\telegram\\utils\\request.py\", line 276, in _request_wrapper\n",
      "    raise Conflict(message)\n",
      "telegram.error.Conflict: Conflict: terminated by other getUpdates request; make sure that only one bot instance is running\n",
      "2021-01-25 15:25:49,727 - telegram.ext.updater - ERROR - Error while getting Updates: Conflict: terminated by other getUpdates request; make sure that only one bot instance is running\n",
      "2021-01-25 15:25:49,728 - telegram.ext.dispatcher - ERROR - No error handlers are registered, logging exception.\n",
      "Traceback (most recent call last):\n",
      "  File \"C:\\Users\\tesya\\anaconda3\\lib\\site-packages\\telegram\\ext\\updater.py\", line 465, in _network_loop_retry\n",
      "    if not action_cb():\n",
      "  File \"C:\\Users\\tesya\\anaconda3\\lib\\site-packages\\telegram\\ext\\updater.py\", line 416, in polling_action_cb\n",
      "    updates = self.bot.get_updates(\n",
      "  File \"<decorator-gen-148>\", line 2, in get_updates\n",
      "  File \"C:\\Users\\tesya\\anaconda3\\lib\\site-packages\\telegram\\bot.py\", line 135, in decorator\n",
      "    result = func(*args, **kwargs)\n",
      "  File \"C:\\Users\\tesya\\anaconda3\\lib\\site-packages\\telegram\\bot.py\", line 2638, in get_updates\n",
      "    result = self._post(\n",
      "  File \"C:\\Users\\tesya\\anaconda3\\lib\\site-packages\\telegram\\bot.py\", line 245, in _post\n",
      "    return self.request.post(f'{self.base_url}/{endpoint}', data=data, timeout=timeout)\n",
      "  File \"C:\\Users\\tesya\\anaconda3\\lib\\site-packages\\telegram\\utils\\request.py\", line 349, in post\n",
      "    result = self._request_wrapper(\n",
      "  File \"C:\\Users\\tesya\\anaconda3\\lib\\site-packages\\telegram\\utils\\request.py\", line 276, in _request_wrapper\n",
      "    raise Conflict(message)\n",
      "telegram.error.Conflict: Conflict: terminated by other getUpdates request; make sure that only one bot instance is running\n"
     ]
    },
    {
     "name": "stderr",
     "output_type": "stream",
     "text": [
      "2021-01-25 15:25:53,749 - telegram.ext.updater - ERROR - Error while getting Updates: Conflict: terminated by other getUpdates request; make sure that only one bot instance is running\n",
      "2021-01-25 15:25:53,749 - telegram.ext.dispatcher - ERROR - No error handlers are registered, logging exception.\n",
      "Traceback (most recent call last):\n",
      "  File \"C:\\Users\\tesya\\anaconda3\\lib\\site-packages\\telegram\\ext\\updater.py\", line 465, in _network_loop_retry\n",
      "    if not action_cb():\n",
      "  File \"C:\\Users\\tesya\\anaconda3\\lib\\site-packages\\telegram\\ext\\updater.py\", line 416, in polling_action_cb\n",
      "    updates = self.bot.get_updates(\n",
      "  File \"<decorator-gen-148>\", line 2, in get_updates\n",
      "  File \"C:\\Users\\tesya\\anaconda3\\lib\\site-packages\\telegram\\bot.py\", line 135, in decorator\n",
      "    result = func(*args, **kwargs)\n",
      "  File \"C:\\Users\\tesya\\anaconda3\\lib\\site-packages\\telegram\\bot.py\", line 2638, in get_updates\n",
      "    result = self._post(\n",
      "  File \"C:\\Users\\tesya\\anaconda3\\lib\\site-packages\\telegram\\bot.py\", line 245, in _post\n",
      "    return self.request.post(f'{self.base_url}/{endpoint}', data=data, timeout=timeout)\n",
      "  File \"C:\\Users\\tesya\\anaconda3\\lib\\site-packages\\telegram\\utils\\request.py\", line 349, in post\n",
      "    result = self._request_wrapper(\n",
      "  File \"C:\\Users\\tesya\\anaconda3\\lib\\site-packages\\telegram\\utils\\request.py\", line 276, in _request_wrapper\n",
      "    raise Conflict(message)\n",
      "telegram.error.Conflict: Conflict: terminated by other getUpdates request; make sure that only one bot instance is running\n",
      "2021-01-25 15:26:05,155 - telegram.ext.updater - ERROR - Error while getting Updates: Conflict: terminated by other getUpdates request; make sure that only one bot instance is running\n",
      "2021-01-25 15:26:05,156 - telegram.ext.dispatcher - ERROR - No error handlers are registered, logging exception.\n",
      "Traceback (most recent call last):\n",
      "  File \"C:\\Users\\tesya\\anaconda3\\lib\\site-packages\\telegram\\ext\\updater.py\", line 465, in _network_loop_retry\n",
      "    if not action_cb():\n",
      "  File \"C:\\Users\\tesya\\anaconda3\\lib\\site-packages\\telegram\\ext\\updater.py\", line 416, in polling_action_cb\n",
      "    updates = self.bot.get_updates(\n",
      "  File \"<decorator-gen-148>\", line 2, in get_updates\n",
      "  File \"C:\\Users\\tesya\\anaconda3\\lib\\site-packages\\telegram\\bot.py\", line 135, in decorator\n",
      "    result = func(*args, **kwargs)\n",
      "  File \"C:\\Users\\tesya\\anaconda3\\lib\\site-packages\\telegram\\bot.py\", line 2638, in get_updates\n",
      "    result = self._post(\n",
      "  File \"C:\\Users\\tesya\\anaconda3\\lib\\site-packages\\telegram\\bot.py\", line 245, in _post\n",
      "    return self.request.post(f'{self.base_url}/{endpoint}', data=data, timeout=timeout)\n",
      "  File \"C:\\Users\\tesya\\anaconda3\\lib\\site-packages\\telegram\\utils\\request.py\", line 349, in post\n",
      "    result = self._request_wrapper(\n",
      "  File \"C:\\Users\\tesya\\anaconda3\\lib\\site-packages\\telegram\\utils\\request.py\", line 276, in _request_wrapper\n",
      "    raise Conflict(message)\n",
      "telegram.error.Conflict: Conflict: terminated by other getUpdates request; make sure that only one bot instance is running\n",
      "2021-01-25 15:26:09,172 - telegram.ext.updater - ERROR - Error while getting Updates: Conflict: terminated by other getUpdates request; make sure that only one bot instance is running\n",
      "2021-01-25 15:26:09,173 - telegram.ext.dispatcher - ERROR - No error handlers are registered, logging exception.\n",
      "Traceback (most recent call last):\n",
      "  File \"C:\\Users\\tesya\\anaconda3\\lib\\site-packages\\telegram\\ext\\updater.py\", line 465, in _network_loop_retry\n",
      "    if not action_cb():\n",
      "  File \"C:\\Users\\tesya\\anaconda3\\lib\\site-packages\\telegram\\ext\\updater.py\", line 416, in polling_action_cb\n",
      "    updates = self.bot.get_updates(\n",
      "  File \"<decorator-gen-148>\", line 2, in get_updates\n",
      "  File \"C:\\Users\\tesya\\anaconda3\\lib\\site-packages\\telegram\\bot.py\", line 135, in decorator\n",
      "    result = func(*args, **kwargs)\n",
      "  File \"C:\\Users\\tesya\\anaconda3\\lib\\site-packages\\telegram\\bot.py\", line 2638, in get_updates\n",
      "    result = self._post(\n",
      "  File \"C:\\Users\\tesya\\anaconda3\\lib\\site-packages\\telegram\\bot.py\", line 245, in _post\n",
      "    return self.request.post(f'{self.base_url}/{endpoint}', data=data, timeout=timeout)\n",
      "  File \"C:\\Users\\tesya\\anaconda3\\lib\\site-packages\\telegram\\utils\\request.py\", line 349, in post\n",
      "    result = self._request_wrapper(\n",
      "  File \"C:\\Users\\tesya\\anaconda3\\lib\\site-packages\\telegram\\utils\\request.py\", line 276, in _request_wrapper\n",
      "    raise Conflict(message)\n",
      "telegram.error.Conflict: Conflict: terminated by other getUpdates request; make sure that only one bot instance is running\n",
      "2021-01-25 15:26:26,275 - telegram.ext.updater - ERROR - Error while getting Updates: Conflict: terminated by other getUpdates request; make sure that only one bot instance is running\n",
      "2021-01-25 15:26:26,276 - telegram.ext.dispatcher - ERROR - No error handlers are registered, logging exception.\n",
      "Traceback (most recent call last):\n",
      "  File \"C:\\Users\\tesya\\anaconda3\\lib\\site-packages\\telegram\\ext\\updater.py\", line 465, in _network_loop_retry\n",
      "    if not action_cb():\n",
      "  File \"C:\\Users\\tesya\\anaconda3\\lib\\site-packages\\telegram\\ext\\updater.py\", line 416, in polling_action_cb\n",
      "    updates = self.bot.get_updates(\n",
      "  File \"<decorator-gen-148>\", line 2, in get_updates\n",
      "  File \"C:\\Users\\tesya\\anaconda3\\lib\\site-packages\\telegram\\bot.py\", line 135, in decorator\n",
      "    result = func(*args, **kwargs)\n",
      "  File \"C:\\Users\\tesya\\anaconda3\\lib\\site-packages\\telegram\\bot.py\", line 2638, in get_updates\n",
      "    result = self._post(\n",
      "  File \"C:\\Users\\tesya\\anaconda3\\lib\\site-packages\\telegram\\bot.py\", line 245, in _post\n",
      "    return self.request.post(f'{self.base_url}/{endpoint}', data=data, timeout=timeout)\n",
      "  File \"C:\\Users\\tesya\\anaconda3\\lib\\site-packages\\telegram\\utils\\request.py\", line 349, in post\n",
      "    result = self._request_wrapper(\n",
      "  File \"C:\\Users\\tesya\\anaconda3\\lib\\site-packages\\telegram\\utils\\request.py\", line 276, in _request_wrapper\n",
      "    raise Conflict(message)\n",
      "telegram.error.Conflict: Conflict: terminated by other getUpdates request; make sure that only one bot instance is running\n",
      "2021-01-25 15:26:30,293 - telegram.ext.updater - ERROR - Error while getting Updates: Conflict: terminated by other getUpdates request; make sure that only one bot instance is running\n",
      "2021-01-25 15:26:30,294 - telegram.ext.dispatcher - ERROR - No error handlers are registered, logging exception.\n",
      "Traceback (most recent call last):\n",
      "  File \"C:\\Users\\tesya\\anaconda3\\lib\\site-packages\\telegram\\ext\\updater.py\", line 465, in _network_loop_retry\n",
      "    if not action_cb():\n",
      "  File \"C:\\Users\\tesya\\anaconda3\\lib\\site-packages\\telegram\\ext\\updater.py\", line 416, in polling_action_cb\n",
      "    updates = self.bot.get_updates(\n",
      "  File \"<decorator-gen-148>\", line 2, in get_updates\n",
      "  File \"C:\\Users\\tesya\\anaconda3\\lib\\site-packages\\telegram\\bot.py\", line 135, in decorator\n",
      "    result = func(*args, **kwargs)\n",
      "  File \"C:\\Users\\tesya\\anaconda3\\lib\\site-packages\\telegram\\bot.py\", line 2638, in get_updates\n",
      "    result = self._post(\n",
      "  File \"C:\\Users\\tesya\\anaconda3\\lib\\site-packages\\telegram\\bot.py\", line 245, in _post\n",
      "    return self.request.post(f'{self.base_url}/{endpoint}', data=data, timeout=timeout)\n",
      "  File \"C:\\Users\\tesya\\anaconda3\\lib\\site-packages\\telegram\\utils\\request.py\", line 349, in post\n",
      "    result = self._request_wrapper(\n",
      "  File \"C:\\Users\\tesya\\anaconda3\\lib\\site-packages\\telegram\\utils\\request.py\", line 276, in _request_wrapper\n",
      "    raise Conflict(message)\n",
      "telegram.error.Conflict: Conflict: terminated by other getUpdates request; make sure that only one bot instance is running\n",
      "2021-01-25 15:26:55,938 - telegram.ext.updater - ERROR - Error while getting Updates: Conflict: terminated by other getUpdates request; make sure that only one bot instance is running\n",
      "2021-01-25 15:26:55,939 - telegram.ext.dispatcher - ERROR - No error handlers are registered, logging exception.\n",
      "Traceback (most recent call last):\n",
      "  File \"C:\\Users\\tesya\\anaconda3\\lib\\site-packages\\telegram\\ext\\updater.py\", line 465, in _network_loop_retry\n",
      "    if not action_cb():\n",
      "  File \"C:\\Users\\tesya\\anaconda3\\lib\\site-packages\\telegram\\ext\\updater.py\", line 416, in polling_action_cb\n",
      "    updates = self.bot.get_updates(\n",
      "  File \"<decorator-gen-148>\", line 2, in get_updates\n",
      "  File \"C:\\Users\\tesya\\anaconda3\\lib\\site-packages\\telegram\\bot.py\", line 135, in decorator\n",
      "    result = func(*args, **kwargs)\n",
      "  File \"C:\\Users\\tesya\\anaconda3\\lib\\site-packages\\telegram\\bot.py\", line 2638, in get_updates\n",
      "    result = self._post(\n",
      "  File \"C:\\Users\\tesya\\anaconda3\\lib\\site-packages\\telegram\\bot.py\", line 245, in _post\n",
      "    return self.request.post(f'{self.base_url}/{endpoint}', data=data, timeout=timeout)\n",
      "  File \"C:\\Users\\tesya\\anaconda3\\lib\\site-packages\\telegram\\utils\\request.py\", line 349, in post\n",
      "    result = self._request_wrapper(\n",
      "  File \"C:\\Users\\tesya\\anaconda3\\lib\\site-packages\\telegram\\utils\\request.py\", line 276, in _request_wrapper\n",
      "    raise Conflict(message)\n",
      "telegram.error.Conflict: Conflict: terminated by other getUpdates request; make sure that only one bot instance is running\n"
     ]
    },
    {
     "name": "stderr",
     "output_type": "stream",
     "text": [
      "2021-01-25 15:26:59,957 - telegram.ext.updater - ERROR - Error while getting Updates: Conflict: terminated by other getUpdates request; make sure that only one bot instance is running\n",
      "2021-01-25 15:26:59,959 - telegram.ext.dispatcher - ERROR - No error handlers are registered, logging exception.\n",
      "Traceback (most recent call last):\n",
      "  File \"C:\\Users\\tesya\\anaconda3\\lib\\site-packages\\telegram\\ext\\updater.py\", line 465, in _network_loop_retry\n",
      "    if not action_cb():\n",
      "  File \"C:\\Users\\tesya\\anaconda3\\lib\\site-packages\\telegram\\ext\\updater.py\", line 416, in polling_action_cb\n",
      "    updates = self.bot.get_updates(\n",
      "  File \"<decorator-gen-148>\", line 2, in get_updates\n",
      "  File \"C:\\Users\\tesya\\anaconda3\\lib\\site-packages\\telegram\\bot.py\", line 135, in decorator\n",
      "    result = func(*args, **kwargs)\n",
      "  File \"C:\\Users\\tesya\\anaconda3\\lib\\site-packages\\telegram\\bot.py\", line 2638, in get_updates\n",
      "    result = self._post(\n",
      "  File \"C:\\Users\\tesya\\anaconda3\\lib\\site-packages\\telegram\\bot.py\", line 245, in _post\n",
      "    return self.request.post(f'{self.base_url}/{endpoint}', data=data, timeout=timeout)\n",
      "  File \"C:\\Users\\tesya\\anaconda3\\lib\\site-packages\\telegram\\utils\\request.py\", line 349, in post\n",
      "    result = self._request_wrapper(\n",
      "  File \"C:\\Users\\tesya\\anaconda3\\lib\\site-packages\\telegram\\utils\\request.py\", line 276, in _request_wrapper\n",
      "    raise Conflict(message)\n",
      "telegram.error.Conflict: Conflict: terminated by other getUpdates request; make sure that only one bot instance is running\n",
      "2021-01-25 15:27:38,421 - telegram.ext.updater - ERROR - Error while getting Updates: Conflict: terminated by other getUpdates request; make sure that only one bot instance is running\n",
      "2021-01-25 15:27:38,422 - telegram.ext.dispatcher - ERROR - No error handlers are registered, logging exception.\n",
      "Traceback (most recent call last):\n",
      "  File \"C:\\Users\\tesya\\anaconda3\\lib\\site-packages\\telegram\\ext\\updater.py\", line 465, in _network_loop_retry\n",
      "    if not action_cb():\n",
      "  File \"C:\\Users\\tesya\\anaconda3\\lib\\site-packages\\telegram\\ext\\updater.py\", line 416, in polling_action_cb\n",
      "    updates = self.bot.get_updates(\n",
      "  File \"<decorator-gen-148>\", line 2, in get_updates\n",
      "  File \"C:\\Users\\tesya\\anaconda3\\lib\\site-packages\\telegram\\bot.py\", line 135, in decorator\n",
      "    result = func(*args, **kwargs)\n",
      "  File \"C:\\Users\\tesya\\anaconda3\\lib\\site-packages\\telegram\\bot.py\", line 2638, in get_updates\n",
      "    result = self._post(\n",
      "  File \"C:\\Users\\tesya\\anaconda3\\lib\\site-packages\\telegram\\bot.py\", line 245, in _post\n",
      "    return self.request.post(f'{self.base_url}/{endpoint}', data=data, timeout=timeout)\n",
      "  File \"C:\\Users\\tesya\\anaconda3\\lib\\site-packages\\telegram\\utils\\request.py\", line 349, in post\n",
      "    result = self._request_wrapper(\n",
      "  File \"C:\\Users\\tesya\\anaconda3\\lib\\site-packages\\telegram\\utils\\request.py\", line 276, in _request_wrapper\n",
      "    raise Conflict(message)\n",
      "telegram.error.Conflict: Conflict: terminated by other getUpdates request; make sure that only one bot instance is running\n",
      "2021-01-25 15:27:42,439 - telegram.ext.updater - ERROR - Error while getting Updates: Conflict: terminated by other getUpdates request; make sure that only one bot instance is running\n",
      "2021-01-25 15:27:42,440 - telegram.ext.dispatcher - ERROR - No error handlers are registered, logging exception.\n",
      "Traceback (most recent call last):\n",
      "  File \"C:\\Users\\tesya\\anaconda3\\lib\\site-packages\\telegram\\ext\\updater.py\", line 465, in _network_loop_retry\n",
      "    if not action_cb():\n",
      "  File \"C:\\Users\\tesya\\anaconda3\\lib\\site-packages\\telegram\\ext\\updater.py\", line 416, in polling_action_cb\n",
      "    updates = self.bot.get_updates(\n",
      "  File \"<decorator-gen-148>\", line 2, in get_updates\n",
      "  File \"C:\\Users\\tesya\\anaconda3\\lib\\site-packages\\telegram\\bot.py\", line 135, in decorator\n",
      "    result = func(*args, **kwargs)\n",
      "  File \"C:\\Users\\tesya\\anaconda3\\lib\\site-packages\\telegram\\bot.py\", line 2638, in get_updates\n",
      "    result = self._post(\n",
      "  File \"C:\\Users\\tesya\\anaconda3\\lib\\site-packages\\telegram\\bot.py\", line 245, in _post\n",
      "    return self.request.post(f'{self.base_url}/{endpoint}', data=data, timeout=timeout)\n",
      "  File \"C:\\Users\\tesya\\anaconda3\\lib\\site-packages\\telegram\\utils\\request.py\", line 349, in post\n",
      "    result = self._request_wrapper(\n",
      "  File \"C:\\Users\\tesya\\anaconda3\\lib\\site-packages\\telegram\\utils\\request.py\", line 276, in _request_wrapper\n",
      "    raise Conflict(message)\n",
      "telegram.error.Conflict: Conflict: terminated by other getUpdates request; make sure that only one bot instance is running\n",
      "2021-01-25 15:28:12,456 - telegram.ext.updater - ERROR - Error while getting Updates: Conflict: terminated by other getUpdates request; make sure that only one bot instance is running\n",
      "2021-01-25 15:28:12,457 - telegram.ext.dispatcher - ERROR - No error handlers are registered, logging exception.\n",
      "Traceback (most recent call last):\n",
      "  File \"C:\\Users\\tesya\\anaconda3\\lib\\site-packages\\telegram\\ext\\updater.py\", line 465, in _network_loop_retry\n",
      "    if not action_cb():\n",
      "  File \"C:\\Users\\tesya\\anaconda3\\lib\\site-packages\\telegram\\ext\\updater.py\", line 416, in polling_action_cb\n",
      "    updates = self.bot.get_updates(\n",
      "  File \"<decorator-gen-148>\", line 2, in get_updates\n",
      "  File \"C:\\Users\\tesya\\anaconda3\\lib\\site-packages\\telegram\\bot.py\", line 135, in decorator\n",
      "    result = func(*args, **kwargs)\n",
      "  File \"C:\\Users\\tesya\\anaconda3\\lib\\site-packages\\telegram\\bot.py\", line 2638, in get_updates\n",
      "    result = self._post(\n",
      "  File \"C:\\Users\\tesya\\anaconda3\\lib\\site-packages\\telegram\\bot.py\", line 245, in _post\n",
      "    return self.request.post(f'{self.base_url}/{endpoint}', data=data, timeout=timeout)\n",
      "  File \"C:\\Users\\tesya\\anaconda3\\lib\\site-packages\\telegram\\utils\\request.py\", line 349, in post\n",
      "    result = self._request_wrapper(\n",
      "  File \"C:\\Users\\tesya\\anaconda3\\lib\\site-packages\\telegram\\utils\\request.py\", line 276, in _request_wrapper\n",
      "    raise Conflict(message)\n",
      "telegram.error.Conflict: Conflict: terminated by other getUpdates request; make sure that only one bot instance is running\n"
     ]
    }
   ],
   "source": [
    "from telegram.ext import CommandHandler\n",
    "start_handler = CommandHandler('start', start)\n",
    "dispatcher.add_handler(start_handler)\n",
    "updater.start_polling()"
   ]
  },
  {
   "cell_type": "code",
   "execution_count": 12,
   "metadata": {},
   "outputs": [
    {
     "name": "stderr",
     "output_type": "stream",
     "text": [
      "2021-01-25 15:28:16,475 - telegram.ext.updater - ERROR - Error while getting Updates: Conflict: terminated by other getUpdates request; make sure that only one bot instance is running\n",
      "2021-01-25 15:28:16,476 - telegram.ext.dispatcher - ERROR - No error handlers are registered, logging exception.\n",
      "Traceback (most recent call last):\n",
      "  File \"C:\\Users\\tesya\\anaconda3\\lib\\site-packages\\telegram\\ext\\updater.py\", line 465, in _network_loop_retry\n",
      "    if not action_cb():\n",
      "  File \"C:\\Users\\tesya\\anaconda3\\lib\\site-packages\\telegram\\ext\\updater.py\", line 416, in polling_action_cb\n",
      "    updates = self.bot.get_updates(\n",
      "  File \"<decorator-gen-148>\", line 2, in get_updates\n",
      "  File \"C:\\Users\\tesya\\anaconda3\\lib\\site-packages\\telegram\\bot.py\", line 135, in decorator\n",
      "    result = func(*args, **kwargs)\n",
      "  File \"C:\\Users\\tesya\\anaconda3\\lib\\site-packages\\telegram\\bot.py\", line 2638, in get_updates\n",
      "    result = self._post(\n",
      "  File \"C:\\Users\\tesya\\anaconda3\\lib\\site-packages\\telegram\\bot.py\", line 245, in _post\n",
      "    return self.request.post(f'{self.base_url}/{endpoint}', data=data, timeout=timeout)\n",
      "  File \"C:\\Users\\tesya\\anaconda3\\lib\\site-packages\\telegram\\utils\\request.py\", line 349, in post\n",
      "    result = self._request_wrapper(\n",
      "  File \"C:\\Users\\tesya\\anaconda3\\lib\\site-packages\\telegram\\utils\\request.py\", line 276, in _request_wrapper\n",
      "    raise Conflict(message)\n",
      "telegram.error.Conflict: Conflict: terminated by other getUpdates request; make sure that only one bot instance is running\n",
      "2021-01-25 15:28:46,508 - telegram.ext.updater - ERROR - Error while getting Updates: Conflict: terminated by other getUpdates request; make sure that only one bot instance is running\n",
      "2021-01-25 15:28:46,510 - telegram.ext.dispatcher - ERROR - No error handlers are registered, logging exception.\n",
      "Traceback (most recent call last):\n",
      "  File \"C:\\Users\\tesya\\anaconda3\\lib\\site-packages\\telegram\\ext\\updater.py\", line 465, in _network_loop_retry\n",
      "    if not action_cb():\n",
      "  File \"C:\\Users\\tesya\\anaconda3\\lib\\site-packages\\telegram\\ext\\updater.py\", line 416, in polling_action_cb\n",
      "    updates = self.bot.get_updates(\n",
      "  File \"<decorator-gen-148>\", line 2, in get_updates\n",
      "  File \"C:\\Users\\tesya\\anaconda3\\lib\\site-packages\\telegram\\bot.py\", line 135, in decorator\n",
      "    result = func(*args, **kwargs)\n",
      "  File \"C:\\Users\\tesya\\anaconda3\\lib\\site-packages\\telegram\\bot.py\", line 2638, in get_updates\n",
      "    result = self._post(\n",
      "  File \"C:\\Users\\tesya\\anaconda3\\lib\\site-packages\\telegram\\bot.py\", line 245, in _post\n",
      "    return self.request.post(f'{self.base_url}/{endpoint}', data=data, timeout=timeout)\n",
      "  File \"C:\\Users\\tesya\\anaconda3\\lib\\site-packages\\telegram\\utils\\request.py\", line 349, in post\n",
      "    result = self._request_wrapper(\n",
      "  File \"C:\\Users\\tesya\\anaconda3\\lib\\site-packages\\telegram\\utils\\request.py\", line 276, in _request_wrapper\n",
      "    raise Conflict(message)\n",
      "telegram.error.Conflict: Conflict: terminated by other getUpdates request; make sure that only one bot instance is running\n",
      "2021-01-25 15:28:50,525 - telegram.ext.updater - ERROR - Error while getting Updates: Conflict: terminated by other getUpdates request; make sure that only one bot instance is running\n",
      "2021-01-25 15:28:50,526 - telegram.ext.dispatcher - ERROR - No error handlers are registered, logging exception.\n",
      "Traceback (most recent call last):\n",
      "  File \"C:\\Users\\tesya\\anaconda3\\lib\\site-packages\\telegram\\ext\\updater.py\", line 465, in _network_loop_retry\n",
      "    if not action_cb():\n",
      "  File \"C:\\Users\\tesya\\anaconda3\\lib\\site-packages\\telegram\\ext\\updater.py\", line 416, in polling_action_cb\n",
      "    updates = self.bot.get_updates(\n",
      "  File \"<decorator-gen-148>\", line 2, in get_updates\n",
      "  File \"C:\\Users\\tesya\\anaconda3\\lib\\site-packages\\telegram\\bot.py\", line 135, in decorator\n",
      "    result = func(*args, **kwargs)\n",
      "  File \"C:\\Users\\tesya\\anaconda3\\lib\\site-packages\\telegram\\bot.py\", line 2638, in get_updates\n",
      "    result = self._post(\n",
      "  File \"C:\\Users\\tesya\\anaconda3\\lib\\site-packages\\telegram\\bot.py\", line 245, in _post\n",
      "    return self.request.post(f'{self.base_url}/{endpoint}', data=data, timeout=timeout)\n",
      "  File \"C:\\Users\\tesya\\anaconda3\\lib\\site-packages\\telegram\\utils\\request.py\", line 349, in post\n",
      "    result = self._request_wrapper(\n",
      "  File \"C:\\Users\\tesya\\anaconda3\\lib\\site-packages\\telegram\\utils\\request.py\", line 276, in _request_wrapper\n",
      "    raise Conflict(message)\n",
      "telegram.error.Conflict: Conflict: terminated by other getUpdates request; make sure that only one bot instance is running\n",
      "2021-01-25 15:29:20,542 - telegram.ext.updater - ERROR - Error while getting Updates: Conflict: terminated by other getUpdates request; make sure that only one bot instance is running\n",
      "2021-01-25 15:29:20,543 - telegram.ext.dispatcher - ERROR - No error handlers are registered, logging exception.\n",
      "Traceback (most recent call last):\n",
      "  File \"C:\\Users\\tesya\\anaconda3\\lib\\site-packages\\telegram\\ext\\updater.py\", line 465, in _network_loop_retry\n",
      "    if not action_cb():\n",
      "  File \"C:\\Users\\tesya\\anaconda3\\lib\\site-packages\\telegram\\ext\\updater.py\", line 416, in polling_action_cb\n",
      "    updates = self.bot.get_updates(\n",
      "  File \"<decorator-gen-148>\", line 2, in get_updates\n",
      "  File \"C:\\Users\\tesya\\anaconda3\\lib\\site-packages\\telegram\\bot.py\", line 135, in decorator\n",
      "    result = func(*args, **kwargs)\n",
      "  File \"C:\\Users\\tesya\\anaconda3\\lib\\site-packages\\telegram\\bot.py\", line 2638, in get_updates\n",
      "    result = self._post(\n",
      "  File \"C:\\Users\\tesya\\anaconda3\\lib\\site-packages\\telegram\\bot.py\", line 245, in _post\n",
      "    return self.request.post(f'{self.base_url}/{endpoint}', data=data, timeout=timeout)\n",
      "  File \"C:\\Users\\tesya\\anaconda3\\lib\\site-packages\\telegram\\utils\\request.py\", line 349, in post\n",
      "    result = self._request_wrapper(\n",
      "  File \"C:\\Users\\tesya\\anaconda3\\lib\\site-packages\\telegram\\utils\\request.py\", line 276, in _request_wrapper\n",
      "    raise Conflict(message)\n",
      "telegram.error.Conflict: Conflict: terminated by other getUpdates request; make sure that only one bot instance is running\n",
      "2021-01-25 15:29:24,563 - telegram.ext.updater - ERROR - Error while getting Updates: Conflict: terminated by other getUpdates request; make sure that only one bot instance is running\n",
      "2021-01-25 15:29:24,564 - telegram.ext.dispatcher - ERROR - No error handlers are registered, logging exception.\n",
      "Traceback (most recent call last):\n",
      "  File \"C:\\Users\\tesya\\anaconda3\\lib\\site-packages\\telegram\\ext\\updater.py\", line 465, in _network_loop_retry\n",
      "    if not action_cb():\n",
      "  File \"C:\\Users\\tesya\\anaconda3\\lib\\site-packages\\telegram\\ext\\updater.py\", line 416, in polling_action_cb\n",
      "    updates = self.bot.get_updates(\n",
      "  File \"<decorator-gen-148>\", line 2, in get_updates\n",
      "  File \"C:\\Users\\tesya\\anaconda3\\lib\\site-packages\\telegram\\bot.py\", line 135, in decorator\n",
      "    result = func(*args, **kwargs)\n",
      "  File \"C:\\Users\\tesya\\anaconda3\\lib\\site-packages\\telegram\\bot.py\", line 2638, in get_updates\n",
      "    result = self._post(\n",
      "  File \"C:\\Users\\tesya\\anaconda3\\lib\\site-packages\\telegram\\bot.py\", line 245, in _post\n",
      "    return self.request.post(f'{self.base_url}/{endpoint}', data=data, timeout=timeout)\n",
      "  File \"C:\\Users\\tesya\\anaconda3\\lib\\site-packages\\telegram\\utils\\request.py\", line 349, in post\n",
      "    result = self._request_wrapper(\n",
      "  File \"C:\\Users\\tesya\\anaconda3\\lib\\site-packages\\telegram\\utils\\request.py\", line 276, in _request_wrapper\n",
      "    raise Conflict(message)\n",
      "telegram.error.Conflict: Conflict: terminated by other getUpdates request; make sure that only one bot instance is running\n",
      "2021-01-25 15:29:54,579 - telegram.ext.updater - ERROR - Error while getting Updates: Conflict: terminated by other getUpdates request; make sure that only one bot instance is running\n",
      "2021-01-25 15:29:54,580 - telegram.ext.dispatcher - ERROR - No error handlers are registered, logging exception.\n",
      "Traceback (most recent call last):\n",
      "  File \"C:\\Users\\tesya\\anaconda3\\lib\\site-packages\\telegram\\ext\\updater.py\", line 465, in _network_loop_retry\n",
      "    if not action_cb():\n",
      "  File \"C:\\Users\\tesya\\anaconda3\\lib\\site-packages\\telegram\\ext\\updater.py\", line 416, in polling_action_cb\n",
      "    updates = self.bot.get_updates(\n",
      "  File \"<decorator-gen-148>\", line 2, in get_updates\n",
      "  File \"C:\\Users\\tesya\\anaconda3\\lib\\site-packages\\telegram\\bot.py\", line 135, in decorator\n",
      "    result = func(*args, **kwargs)\n",
      "  File \"C:\\Users\\tesya\\anaconda3\\lib\\site-packages\\telegram\\bot.py\", line 2638, in get_updates\n",
      "    result = self._post(\n",
      "  File \"C:\\Users\\tesya\\anaconda3\\lib\\site-packages\\telegram\\bot.py\", line 245, in _post\n",
      "    return self.request.post(f'{self.base_url}/{endpoint}', data=data, timeout=timeout)\n",
      "  File \"C:\\Users\\tesya\\anaconda3\\lib\\site-packages\\telegram\\utils\\request.py\", line 349, in post\n",
      "    result = self._request_wrapper(\n",
      "  File \"C:\\Users\\tesya\\anaconda3\\lib\\site-packages\\telegram\\utils\\request.py\", line 276, in _request_wrapper\n",
      "    raise Conflict(message)\n",
      "telegram.error.Conflict: Conflict: terminated by other getUpdates request; make sure that only one bot instance is running\n"
     ]
    },
    {
     "name": "stderr",
     "output_type": "stream",
     "text": [
      "2021-01-25 15:29:58,598 - telegram.ext.updater - ERROR - Error while getting Updates: Conflict: terminated by other getUpdates request; make sure that only one bot instance is running\n",
      "2021-01-25 15:29:58,599 - telegram.ext.dispatcher - ERROR - No error handlers are registered, logging exception.\n",
      "Traceback (most recent call last):\n",
      "  File \"C:\\Users\\tesya\\anaconda3\\lib\\site-packages\\telegram\\ext\\updater.py\", line 465, in _network_loop_retry\n",
      "    if not action_cb():\n",
      "  File \"C:\\Users\\tesya\\anaconda3\\lib\\site-packages\\telegram\\ext\\updater.py\", line 416, in polling_action_cb\n",
      "    updates = self.bot.get_updates(\n",
      "  File \"<decorator-gen-148>\", line 2, in get_updates\n",
      "  File \"C:\\Users\\tesya\\anaconda3\\lib\\site-packages\\telegram\\bot.py\", line 135, in decorator\n",
      "    result = func(*args, **kwargs)\n",
      "  File \"C:\\Users\\tesya\\anaconda3\\lib\\site-packages\\telegram\\bot.py\", line 2638, in get_updates\n",
      "    result = self._post(\n",
      "  File \"C:\\Users\\tesya\\anaconda3\\lib\\site-packages\\telegram\\bot.py\", line 245, in _post\n",
      "    return self.request.post(f'{self.base_url}/{endpoint}', data=data, timeout=timeout)\n",
      "  File \"C:\\Users\\tesya\\anaconda3\\lib\\site-packages\\telegram\\utils\\request.py\", line 349, in post\n",
      "    result = self._request_wrapper(\n",
      "  File \"C:\\Users\\tesya\\anaconda3\\lib\\site-packages\\telegram\\utils\\request.py\", line 276, in _request_wrapper\n",
      "    raise Conflict(message)\n",
      "telegram.error.Conflict: Conflict: terminated by other getUpdates request; make sure that only one bot instance is running\n"
     ]
    }
   ],
   "source": [
    "def echo(update, context):\n",
    "    context.bot.send_message(chat_id=update.effective_chat.id, text=update.message.text)\n",
    "\n",
    "from telegram.ext import MessageHandler, Filters\n",
    "echo_handler = MessageHandler(Filters.text & (~Filters.command), echo)\n",
    "dispatcher.add_handler(echo_handler)"
   ]
  },
  {
   "cell_type": "code",
   "execution_count": null,
   "metadata": {},
   "outputs": [],
   "source": []
  }
 ],
 "metadata": {
  "kernelspec": {
   "display_name": "Python 3",
   "language": "python",
   "name": "python3"
  },
  "language_info": {
   "codemirror_mode": {
    "name": "ipython",
    "version": 3
   },
   "file_extension": ".py",
   "mimetype": "text/x-python",
   "name": "python",
   "nbconvert_exporter": "python",
   "pygments_lexer": "ipython3",
   "version": "3.8.5"
  }
 },
 "nbformat": 4,
 "nbformat_minor": 4
}
